Workbook

Sheet Sheet1
A1: Prüfmerkmal | B1: Prüfmerkmal_Text_Voll | C1: Irrelevant_1 | D1: Prüfmerkmal_Text | E1: Irrelevant_2 | F1: Fertigungshilfsmittel | G1: Qualitatives_Merkmal | H1: Sollwert | I1: Merkmalsgewichtung | J1: Maßeinheit | K1: Oberer_Grenzwert | L1: Unterer_Grenzwert | M1: Nachkommastellen | N1: Stichprobenverfahren | O1: Irrelevant_3 | P1: Vorgang | Q1: Lenkungsmethode | R1: Plangruppe | S1: Knotenplan | T1: Verbindung | U1: Arbeitsplatz | V1: Beschreibung_Vorgang
A2: 150 | B2: Bohrungs-ø 37,226 +0,04 | E2: 14 | F2: MESSUHR | H2: 37,226 | J2: mm | K2: 37,266 | L2: 37,226 | M2: 3 | N2: 1/1 | O2: 100% Prüfung | P2: 0048 | Q2: 80 | R2: 50000000 | S2: 4 | T2: =R2&S2 -> 500000004 | U2: =VLOOKUP(T:T,Tabelle1!F:H,2,TRUE) -> 96161 | V2: =VLOOKUP(T:T,Tabelle1!F:H,3,TRUE) -> CNC-Drehen
A3: 160 | B3: Rundheit max. 0,018 | E3: 1 | F3: FORM- UND LAGEMESSGERÄT | H3: 0,000 | J3: mm | K3: 0,018 | L3: 0,000 | M3: 3 | N3: 1/444 | O3: 1 Teil pro Schicht | P3: 0048 | Q3: 20 | R3: 50000000 | S3: 4 | T3: =R3&S3 -> 500000004 | U3: =VLOOKUP(T:T,Tabelle1!F:H,2,TRUE) -> 96161 | V3: =VLOOKUP(T:T,Tabelle1!F:H,3,TRUE) -> CNC-Drehen
A4: 170 | B4: Sichtprüfung der Oberflächen und | D4: Sichtprüfung allg. | E4: 46 | F4: visuelle Prüfung | G4: X | M4: 0 | N4: 1/60 | O4: 1 Teil pro 60min | P4: 0048 | Q4: 20 | R4: 50000000 | S4: 4 | T4: =R4&S4 -> 500000004 | U4: =VLOOKUP(T:T,Tabelle1!F:H,2,TRUE) -> 96161 | V4: =VLOOKUP(T:T,Tabelle1!F:H,3,TRUE) -> CNC-Drehen
A5: 180 | B5: Maschinenabnahme gemäß Pb 8.5.1.3 | D5: Maschinenabnahme gemäß Pb 8.5.1.3 | E5: 45 | F5: SONST. MESSMITTEL | G5: X | M5: 0 | N5: 1/CH. | O5: 1 Teil pro Charge/ FA | P5: 0048 | Q5: 11 | R5: 50000000 | S5: 4 | T5: =R5&S5 -> 500000004 | U5: =VLOOKUP(T:T,Tabelle1!F:H,2,TRUE) -> 96161 | V5: =VLOOKUP(T:T,Tabelle1!F:H,3,TRUE) -> CNC-Drehen
A6: 190 | B6: Prozessparameter gem. Einstelldatenblatt | D6: Prozessparameter gem. Einstelldatenblatt | E6: 46 | F6: visuelle Prüfung | G6: X | M6: 0 | N6: 1/CH. | O6: 1 Teil pro Charge/ FA | P6: 0048 | Q6: 11 | R6: 50000000 | S6: 4 | T6: =R6&S6 -> 500000004 | U6: =VLOOKUP(T:T,Tabelle1!F:H,2,TRUE) -> 96161 | V6: =VLOOKUP(T:T,Tabelle1!F:H,3,TRUE) -> CNC-Drehen
A7: 200 | B7: Zwischenprüfung gemäß Pb 8.5.1.1 | D7: Zwischenprüfung gemäß Pb 8.5.1.1 | E7: 45 | F7: SONST. MESSMITTEL | G7: X | M7: 0 | N7: TEST-5 | O7: Einfach-Stichprobenverf. Test-5 PB 8.5.1 | P7: 0048 | Q7: 16 | R7: 50000000 | S7: 4 | T7: =R7&S7 -> 500000004 | U7: =VLOOKUP(T:T,Tabelle1!F:H,2,TRUE) -> 96161 | V7: =VLOOKUP(T:T,Tabelle1!F:H,3,TRUE) -> CNC-Drehen
A8: 150 | B8: Bohrungs-ø 37,226 +0,04 | E8: 32 | F8: MESSUHR | H8: 37,226 | J8: mm | K8: 37,266 | L8: 37,226 | M8: 3 | N8: 1/1 | O8: 100% Prüfung | P8: 0048 | Q8: 80 | R8: 50000000 | S8: 20 | T8: =R8&S8 -> 5000000020 | U8: =VLOOKUP(T:T,Tabelle1!F:H,2,FALSE) -> 96161 | V8: =VLOOKUP(T:T,Tabelle1!F:H,3,FALSE) -> CNC-Drehen
A9: 160 | B9: Rundheit max. 0,018 | E9: 30 | F9: FORM- UND LAGEMESSGERÄT | H9: 0,000 | J9: mm | K9: 0,018 | L9: 0,000 | M9: 3 | N9: 1/444 | O9: 1 Teil pro Schicht | P9: 0048 | Q9: 20 | R9: 50000000 | S9: 20 | T9: =R9&S9 -> 5000000020 | U9: =VLOOKUP(T:T,Tabelle1!F:H,2,FALSE) -> 96161 | V9: =VLOOKUP(T:T,Tabelle1!F:H,3,FALSE) -> CNC-Drehen
A10: 170 | B10: Sichtprüfung der Oberflächen und | D10: Sichtprüfung allg. | E10: 71 | F10: visuelle Prüfung | G10: X | M10: 0 | N10: 1/60 | O10: 1 Teil pro 60min | P10: 0048 | Q10: 20 | R10: 50000000 | S10: 20 | T10: =R10&S10 -> 5000000020 | U10: =VLOOKUP(T:T,Tabelle1!F:H,2,FALSE) -> 96161 | V10: =VLOOKUP(T:T,Tabelle1!F:H,3,FALSE) -> CNC-Drehen

Sheet Tabelle1
A1: Plangruppenzähler | B1: Folge | C1: Plantyp | D1: Plangruppe | E1: KnotenPlan | G1: Arbeitsplatz | H1: Kurztext Vorgang | I1: Gültig ab
A2: 1 | B2: 0 | C2: N | D2: 50000000 | E2: 4 | F2: =D2&E2 -> 500000004 | G2: 96161 | H2: CNC-Drehen | I2: 40179
A3: 2 | B3: 0 | C3: N | D3: 50000000 | E3: 20 | F3: =D3&E3 -> 5000000020 | G3: 96161 | H3: CNC-Drehen | I3: 41690
A4: 1 | B4: 0 | C4: N | D4: 50000001 | E4: 4 | F4: =D4&E4 -> 500000014 | G4: 96161 | H4: Komplett fertigdrehen | I4: 40179
A5: 1 | B5: 0 | C5: N | D5: 50000002 | E5: 6 | F5: =D5&E5 -> 500000026 | G5: 96161 | H5: CNC-Drehen 49/H | I5: 40179
A6: 1 | B6: 0 | C6: N | D6: 50000003 | E6: 2 | F6: =D6&E6 -> 500000032 | G6: 96161 | H6: CNC-Drehen | I6: 40179
A7: 2 | B7: 0 | C7: N | D7: 50000003 | E7: 8 | F7: =D7&E7 -> 500000038 | G7: INDEX C | H7: Drehen | I7: 45461
A8: 1 | B8: 0 | C8: N | D8: 50000005 | E8: 2 | F8: =D8&E8 -> 500000052 | G8: AF32 | H8: Drehen ohne Querbohrungen | I8: 40179
A9: 1 | B9: 0 | C9: N | D9: 50000006 | E9: 6 | F9: =D9&E9 -> 500000066 | G9: 96161 | H9: Außen feindrehen, rollieren und Ventilsi | I9: 40179
A10: 1 | B10: 0 | C10: N | D10: 50000007 | E10: 11 | F10: =D10&E10 -> 5000000711 | G10: S32PC | H10: Aussenkontur vordrehen - im Bereich der | I10: 40179
A11: 1 | B11: 0 | C11: N | D11: 50000007 | E11: 6 | F11: =D11&E11 -> 500000076 | G11: 161SIRNG | H11: Fertigdrehen und auf beigestellten Stabd | I11: 40179
A12: 1 | B12: 0 | C12: N | D12: 50000007 | E12: 1 | F12: =D12&E12 -> 500000071 | G12: 161SIRNG | H12: Stabdorn auf Transportbrett setzen | I12: 40179
A13: 2 | B13: 0 | C13: N | D13: 50000007 | E13: 12 | F13: =D13&E13 -> 5000000712 | G13: S32PC | H13: Aussenkontur vordrehen und Stege fräsen | I13: 40679
... A1655: 1 | B1655: 0 | C1655: N | D1655: 50026731 | E1655: 1 | F1655: =D1655&E1655 -> 500267311 | G1655: INDEX C | H1655: Drehen komplett C100 | I1655: 45594

Sheet Tabelle2
A1: Kurztext | B1: Prüfmerkmal
A2: Bohrungs-ø | B2: 37.226 | C2: 0.04
A3: Rundheit | B3: max. | C3: 0.018
A4: Sichtprüfung | B4: der | C4: Oberflächen | D4: und
A5: Maschinenabnahme | B5: gemäß | C5: Pb | D5: 8.5.1.3
A6: Prozessparameter | B6: gem. | C6: Einstelldatenblatt
A7: Zwischenprüfung | B7: gemäß | C7: Pb | D7: 8.5.1.1
A8: Bohrungs-ø | B8: 37.226 | C8: 0.04
A9: Rundheit | B9: max. | C9: 0.018
A10: Sichtprüfung | B10: der | C10: Oberflächen | D10: und
A11: Maschinenabnahme | B11: gemäß | C11: Pb | D11: 8.5.1.3
A12: Prozessparameter | B12: gem. | C12: Einstelldatenblatt
A13: Zwischenprüfung | B13: gemäß | C13: Pb | D13: 8.5.1.1
A14: Länge | B14: 59.25 | C14: +/-0,05
A15: Abstand | B15: 0 | C15: 0.38
A16: Abstand | B16: 5 | C16: +/-0,1
A17: Abstand | B17: 46 | C17: +/-0,1
A18: Gewindetiefe | B18: 10.5 | C18: 2
A19: Aussen-ø | B19: 8 | C19: +/-0,2
A20: Aussen-ø | B20: 6 | C20: h6-0/-0,008
A21: Gewinde | B21: M4 | C21: - | D21: 6g
A22: Koaxialität | B22: max. | C22: 0.01
A23: Sichtprüfung | B23: der | C23: Oberflächen | D23: und
A24: Länge | B24: 44.25 | C24: +/-0,05
A25: Aussen-ø | B25: 6 | C25: h6 | D25: 0/-0,008
A26: Abstand | B26: 6 | C26: +/-0,1
A27: Abstand | B27: 31 | C27: +/-0,1
A28: Abstand | B28: 0 | C28: 0.38
A29: Aussen-ø | B29: 8 | C29: -0.09
A30: Gewinde | B30: M4 | C30: - | D30: 6g
A31: Gewindelänge | B31: 10.5 | C31: 2
A32: Koaxialität | B32: max. | C32: 0.01 | D32: zu | E32: A
A33: Sichtprüfung | B33: der | C33: Oberflächen | D33: und
A34: siehe | B34: produktspezifische | C34: AA
A35: siehe | B35: allgem. | C35: prozessbezogene | D35: AA
A36: Abstand | B36: 29.5 | C36: +/-0,15
A37: Abstand | B37: 9.5 | C37: 0.2
A38: Aussen-ø | B38: 14 | C38: +/-0,03
A39: Abstand | B39: 6 | C39: +/-0,1
A40: Aussen-ø | B40: 6 | C40: h6 | D40: 0/-0,008
...
